Workbook
Name UPDATE: 'Data Sheet'!$E$1

Sheet Executive Summary
B2: ="NESTLÉ INDIA — FP&A ANALYSIS | "&'Data Sheet'!B1&" | Executive Summary" -> NESTLÉ INDIA — FP&A ANALYSIS | NESTLE INDIA LTD | Executive Summary
B5: A. Company Overview | J5: B. Project Objective
B6: • Nestlé India Ltd is a subsidiary of Nestlé S.A. (Switzerland), listed on the BSE/NSE. • Core business: packaged food and beverages (nutrition, confectionery, beverages, dairy). • Major categories include instant noodles, coffee, milk products, chocolates & confectionery, and infant nutrition. • Manufactures and distributes across India through multiple factories and a pan-India distribution network. | J6: This project demonstrates an end-to-end FP&A workflow: • Historical financial analysis and ratio trends • Assumption building (revenue growth, cost ratios, monthly seasonality) • Derived monthly actuals from quarterly reported data • Monthly budgeting and a 12-month forward forecast • Budget vs Actual and Budget vs Forecast variance analysis • Management dashboards
B11: C. Data Used | J11: D. Methodology Flow
B12: • Historical annual and quarterly financials sourced from Nestlé India's publicly reported financial statements (Data Sheet tab). • Monthly company-reported P&L data is NOT publicly available. • Monthly figures are therefore DERIVED from reported quarterly data using an explicit allocation assumption (31% / 33% / 36% of each quarter). • Derived monthly figures are modelled estimates and are NOT company-reported monthly results. • FY2023-24 was a 15-month transition year (Nestlé India changed its financial year-end from December to March) and is not directly comparable with normal 12-month years in trend analyses (see Historical FS / Ratio Analysis). | J12: Historical Financials → Historical Analysis → Assumptions → Quarterly-to-Monthly Allocation → Derived Monthly Actuals → Monthly Budget → 12-Month Forecast → Budget vs Actual / Budget vs Forecast → Variance Analysis → Management Dashboard
B17: E. Key Assumptions
B18: Assumption | G18: Base / Historical | I18: Budget | K18: Forecast | M18: Unit | P18: Type
B19: Revenue Growth, YoY | G19: =Assumptions!C11 -> 0.14617881 | I19: =Assumptions!D11 -> 0.1 | K19: =Assumptions!E11 -> 0.12 | M19: % p.a. | P19: Historical trend / Analyst assumption
B20: COGS / Material Cost % of Revenue | G20: =Assumptions!C15 -> 0.39361336 | I20: =Assumptions!D15 -> 0.388 | K20: =Assumptions!E15 -> 0.395 | M20: % of revenue | P20: Historical average / Analyst assumption
B21: Employee Cost % of Revenue | G21: =Assumptions!C16 -> 0.098399886 | I21: =Assumptions!D16 -> 0.102 | K21: =Assumptions!E16 -> 0.1 | M21: % of revenue | P21: Historical average / Analyst assumption
B22: Other Operating Expenses % of Revenue | G22: =Assumptions!C17 -> 0.27878996 | I22: =Assumptions!D17 -> 0.281 | K22: =Assumptions!E17 -> 0.285 | M22: % of revenue | P22: Historical average / Analyst assumption
B23: Depreciation — YoY growth (simplified driver) | I23: =Assumptions!D22 -> 0.104 | K23: =Assumptions!E22 -> 0.105 | M23: % YoY | P23: Analyst assumption
B24: Interest — YoY growth (simplified driver) | I24: =Assumptions!D23 -> 0.075 | K24: =Assumptions!E23 -> 0.085 | M24: % YoY | P24: Analyst assumption
B25: Effective Tax Rate | G25: =Assumptions!C25 -> 0.23104791 | I25: =Assumptions!D25 -> 0.232 | K25: =Assumptions!E25 -> 0.235 | M25: % of EBT | P25: Historical average / Analyst assumption
B26: Monthly Allocation (Seasonality) | G26: =TEXT(Assumptions!E4,"0%")&" / "&TEXT(Assumptions!E5,"0%")&" / "&TEXT(Assumptions!E6,"0%")&" (Month 1/2/3 of quarter)" -> 31% / 33% / 36% (Month 1/2/3 of quarter) | P26: Analyst assumption
B28: F. Key Financial Analysis (₹ Crore unless %)
B29: Metric | H29: Historical (Last 12-mo Actual) | K29: Budget (12-mo) | N29: Forecast (12-mo) | Q29: Budget vs Forecast Var %
B30: Revenue | H30: ='Monthly Actuals'!C26 -> 24436.62 | K30: ='Monthly Budget'!C23 -> 26372.602 | N30: ='Rolling Forecast'!C25 -> 26852.104 | Q30: =IFERROR((N30-K30)/ABS(K30),0) -> 0.018181818
B31: EBITDA | H31: ='Monthly Actuals'!C27 -> 5747.32 | K31: ='Monthly Budget'!C24 -> 6039.3259 | N31: ='Rolling Forecast'!C26 -> 5907.4629 | Q31: =IFERROR((N31-K31)/ABS(K31),0) -> -0.021834061
B32: EBITDA Margin % | H32: ='Monthly Actuals'!C27/'Monthly Actuals'!C26 -> 0.23519292 | K32: ='Monthly Budget'!C24/'Monthly Budget'!C23 -> 0.229 | N32: ='Rolling Forecast'!C26/'Rolling Forecast'!C25 -> 0.22 | Q32: =IFERROR((N32-K32)/ABS(K32),0) -> -0.03930131
B33: PAT | H33: ='Monthly Actuals'!C28 -> 3860.49 | K33: ='Monthly Budget'!C25 -> 4024.0193 | N33: ='Rolling Forecast'!C27 -> 3926.3308 | Q33: =IFERROR((N33-K33)/ABS(K33),0) -> -0.02427635
B34: COGS % of Revenue | H34: =Assumptions!C15 -> 0.39361336 | K34: =Assumptions!D15 -> 0.388 | N34: =Assumptions!E15 -> 0.395 | Q34: =IFERROR((N34-K34)/ABS(K34),0) -> 0.018041237
B35: Employee Cost % of Revenue | H35: =Assumptions!C16 -> 0.098399886 | K35: =Assumptions!D16 -> 0.102 | N35: =Assumptions!E16 -> 0.1 | Q35: =IFERROR((N35-K35)/ABS(K35),0) -> -0.019607843
B36: Other Opex % of Revenue | H36: =Assumptions!C17 -> 0.27878996 | K36: =Assumptions!D17 -> 0.281 | N36: =Assumptions!E17 -> 0.285 | Q36: =IFERROR((N36-K36)/ABS(K36),0) -> 0.014234875
B38: Historical = trailing 12-month Derived Monthly Actual (not company-reported monthly data — see Section C and Assumptions notes).
B40: G. Key Management Insights | J40: H. Limitations
B41: • Full-year Budget vs Forecast: Forecast revenue runs above Budget, but Forecast cost ratios (COGS/Employee/Other Opex) are all set slightly higher than Budget's — a modelling choice (Assumptions Forecast column), not a bottom-up cost forecast. See Variance Analysis Part 2. • EBITDA margin: driven mechanically by the three cost-ratio assumptions in Assumptions Section C; the Budget vs Forecast margin gap reflects those assumption settings, not an operational finding. • Employee cost represents one of three cost lines split from Total Opex using the Section E cost-mix assumption (~13% of Opex) — an analyst approximation, since the quarterly source does not report this split. • Depreciation and Interest are modelled on a simplified YoY-growth basis (Assumptions Section D), not a full fixed-asset/debt schedule — see Model Checks limitations. • The largest Budget vs Forecast variance driver is the compounding effect of the cost-ratio assumptions across 12 months — see Variance Analysis 'Driver / Explanation' column for the full line-by-line breakdown. • All figures above are model outputs from stated assumptions, not independently verified operational explanations. | J41: 1. Monthly actuals are DERIVED from quarterly reported data using an allocation assumption — they are not company-reported monthly actuals. 2. The monthly allocation percentages (31/33/36) and the cost-mix split (Section E) are modelled estimates, not reported splits. 3. Budget and Forecast results depend entirely on analyst assumptions (Assumptions sheet, Budget/Forecast columns) — they are not company guidance. 4. Depreciation/Interest use a simplified YoY-growth methodology; no monthly/quarterly PP&E or debt schedule is available. 5. This model is intended for portfolio / analytical demonstration only, and is NOT Nestlé India's internal planning model. 6. FY2023-24 was a 15-month transition year (calendar-year to April–March fiscal-year change) and is not directly comparable with normal 12-month periods for growth/trend metrics.
B50: Derived monthly figures are modelled estimates and are not company-reported monthly results. See Assumptions sheet and Model Checks sheet for full methodology, source labelling and integrity checks.

Sheet Budget VS Actual Dashboard
B2: ="Management Dashboard for Q1 (Apr-26 to Jun-26) -"&'Data Sheet'!B1 -> Management Dashboard for Q1 (Apr-26 to Jun-26) -NESTLE INDIA LTD
B3: Revenue | F3: EBITDA Margin | J3: EBITDA | N3: Opex
B4: =SUM('Budget VS Actuals'!C8:E8) -> 6378.18 | F4: ='Variance Analysis'!D10/'Variance Analysis'!D6 -> 0.241155 | J4: =SUM('Budget VS Actuals'!C32:E32) -> 1538.13 | N4: =SUM('Monthly Actuals'!AD10:AF10) -> 4840.05
B5: vs Budget | C5: =(SUM('Budget VS Actuals'!C8:E8)-SUM('Budget VS Actuals'!C7:E7))/SUM('Budget VS Actuals'!C7:E7) -> 0.10593414 | D5: =IF(C5>0,"Increased","Decreased") -> Increased | F5: vs Budget | G5: =F4-('Variance Analysis'!C10/'Variance Analysis'!C6) -> 0.012155 | H5: =IF(G5>0,"Increased","Decreased") -> Increased | J5: vs Budget | K5: =(SUM('Budget VS Actuals'!C32:E32)-SUM('Budget VS Actuals'!C31:E31))/SUM('Budget VS Actuals'!C31:E31) -> 0.16463558 | L5: =IF(K5>0,"Increased","Decreased") -> Increased | N5: vs Budget | O5: =(SUM('Monthly Actuals'!AD10:AF10)-SUM('Monthly Budget'!C8:E8))/SUM('Monthly Budget'!C8:E8) -> 0.088498822 | P5: =IF(O5>0,"Increased","Decreased") -> Increased
B6: Note: 'Actual' figures are Derived Monthly Actuals - not company-reported - allocated from Nestle India's reported quarterly results using the seasonality assumption on the Assumptions sheet (see Assumptions!B34:B38).
B7: Revenue & Cost structure - Q1 FY26-27 Budget to Actual (Rs Crore)
B8: Revenue
B9: Month | C9: Actual (Derived) | D9: Budget | E9: Variance | F9: Variance % | J9: Cost Line | K9: Budget | L9: Actual (Derived) | M9: Variance %
B10: 46113 | C10: ='Budget VS Actuals'!C8 -> 1977.2358 | D10: ='Budget VS Actuals'!C7 -> 2179.5365 | E10: =C10-D10 -> -202.30068 | F10: =E10/D10 -> -0.092818212 | J10: COGS | K10: ='Variance Analysis'!C7 -> 2237.6865 | L10: ='Variance Analysis'!D7 -> 2395.8248 | M10: ='Variance Analysis'!F7 -> 0.070670446
B11: 46143 | C11: ='Budget VS Actuals'!D8 -> 2104.7994 | D11: ='Budget VS Actuals'!D7 -> 1737.7906 | E11: =C11-D11 -> 367.00884 | F11: =E11/D11 -> 0.21119279 | J11: Employee Cost | K11: ='Variance Analysis'!C8 -> 588.25778 | L11: ='Variance Analysis'!D8 -> 638.8866 | M11: ='Variance Analysis'!F8 -> 0.086065707
B12: 46174 | C12: ='Budget VS Actuals'!E8 -> 2296.1448 | D12: ='Budget VS Actuals'!E7 -> 1849.9061 | E12: =C12-D12 -> 446.23872 | F12: =E12/D12 -> 0.24122237 | J12: Other Operating Expenses | K12: ='Variance Analysis'!C9 -> 1620.5925 | L12: ='Variance Analysis'!D9 -> 1805.3387 | M12: ='Variance Analysis'!F9 -> 0.11399913
J29: ="What this shows: all three cost lines ran hotter than budget in Q1 (COGS +"&TEXT('Variance Analysis'!F7,"0.0%")&", Employee +"&TEXT('Variance Analysis'!F8,"0.0%")&", Other Opex +"&TEXT('Variance Analysis'!F9,"0.0%")&"), in line with the cost-ratio assumptions on the Assumptions sheet, not a one-off spend spike in any single line." -> What this shows: all three cost lines ran hotter than budget in Q1 (COGS +7.1%, Employee +8.6%, Other Opex +11.4%), in line with the cost-ratio assumptions on the Assumptions sheet, not a one-off spend spike in any single line.
B31: EBITDA Bridge - Q1 FY26-27 Budget to Actual (Rs Crore)
B33: Category | C33: Type | D33: Net Impact (Rs Cr) | E33: Running Total | F33: Base | G33: Increase | H33: Decrease | I33: Total
B34: Q1 Budget EBITDA | C34: Total | D34: ='Variance Analysis'!C10 -> 1320.6964 | E34: =D34 -> 1320.6964 | F34: =0 -> 0 | G34: =IF(C34="Increase",MAX(D34,0),0) -> 0 | H34: =IF(C34="Decrease",MAX(-D34,0),0) -> 0 | I34: =IF(C34="Total",D34,0) -> 1320.6964
B35: Revenue Variance | C35: Increase | D35: ='Variance Analysis'!D6-'Variance Analysis'!C6 -> 610.94688 | E35: =IF(C35="Total",D35,E34+D35) -> 1931.6433 | F35: =IF(C35="Total",0,MIN(E34,E35)) -> 1320.6964 | G35: =IF(C35="Increase",MAX(D35,0),0) -> 610.94688 | H35: =IF(C35="Decrease",MAX(-D35,0),0) -> 0 | I35: =IF(C35="Total",D35,0) -> 0
B36: COGS Impact | C36: Decrease | D36: =-('Variance Analysis'!D7-'Variance Analysis'!C7) -> -158.1383 | E36: =IF(C36="Total",D36,E35+D36) -> 1773.505 | F36: =IF(C36="Total",0,MIN(E35,E36)) -> 1773.505 | G36: =IF(C36="Increase",MAX(D36,0),0) -> 0 | H36: =IF(C36="Decrease",MAX(-D36,0),0) -> 158.1383 | I36: =IF(C36="Total",D36,0) -> 0
B37: Employee Cost Impact | C37: Decrease | D37: =-('Variance Analysis'!D8-'Variance Analysis'!C8) -> -50.628822 | E37: =IF(C37="Total",D37,E36+D37) -> 1722.8761 | F37: =IF(C37="Total",0,MIN(E36,E37)) -> 1722.8761 | G37: =IF(C37="Increase",MAX(D37,0),0) -> 0 | H37: =IF(C37="Decrease",MAX(-D37,0),0) -> 50.628822 | I37: =IF(C37="Total",D37,0) -> 0
B38: Other Opex Impact | C38: Decrease | D38: =-('Variance Analysis'!D9-'Variance Analysis'!C9) -> -184.74614 | E38: =IF(C38="Total",D38,E37+D38) -> 1538.13 | F38: =IF(C38="Total",0,MIN(E37,E38)) -> 1538.13 | G38: =IF(C38="Increase",MAX(D38,0),0) -> 0 | H38: =IF(C38="Decrease",MAX(-D38,0),0) -> 184.74614 | I38: =IF(C38="Total",D38,0) -> 0
B39: Q1 Actual EBITDA | C39: Total | D39: ='Variance Analysis'!D10 -> 1538.13 | E39: =IF(C39="Total",D39,E38+D39) -> 1538.13 | F39: =IF(C39="Total",0,MIN(E38,E39)) -> 0 | G39: =IF(C39="Increase",MAX(D39,0),0) -> 0 | H39: =IF(C39="Decrease",MAX(-D39,0),0) -> 0 | I39: =IF(C39="Total",D39,0) -> 1538.13
B52: ="What this shows: EBITDA moved from Rs "&TEXT('Variance Analysis'!C10,"#,##0")&" Cr (budget) to Rs "&TEXT('Variance Analysis'!D10,"#,##0")&" Cr (actual), a "&TEXT('Variance Analysis'!F10,"+0.0%;-0.0%")&" beat. "&"Higher revenue added Rs "&TEXT('Variance Analysis'!D6-'Variance Analysis'!C6,"#,##0")&" Cr, which more than offset cost overruns "&"in COGS, employee cost and other opex (each ran ahead of budget by roughly "&TEXT('Variance Analysis'!F7,"0.0%")&"). "&"April alone missed budget on revenue; May and June both beat it - worth checking what changed after April." -> What this shows: EBITDA moved from Rs 1,321 Cr (budget) to Rs 1,538 Cr (actual), a +16.5% beat. Higher revenue added Rs 611 Cr, which more than offset cost overruns in COGS, employee cost and other opex (each ran ahead of budget by roughly 7.1%). April alone missed budget on revenue; May and June both beat it - worth checking what changed after April.
B56: EBITDA Margin Trend & PAT - Actual vs Budget (Q1 FY26-27)
B58: Month | C58: Budget Margin % | D58: Actual Margin % | J58: Month | K58: Budget | L58: Actual (Derived) | M58: Variance %
B59: =B10 -> 46113 | C59: ='Monthly Budget'!C13 -> 0.229 | D59: ='Monthly Actuals'!AD15 -> 0.241155 | J59: =B10 -> 46113 | K59: ='Budget VS Actuals'!C55 -> 340.94869 | L59: ='Budget VS Actuals'!C56 -> 302.2872 | M59: ='Budget VS Actuals'!C58 -> -0.11339386
B60: =B11 -> 46143 | C60: ='Monthly Budget'!D13 -> 0.229 | D60: ='Monthly Actuals'!AE15 -> 0.241155 | J60: =B11 -> 46143 | K60: ='Budget VS Actuals'!D55 -> 257.6172 | L60: ='Budget VS Actuals'!D56 -> 321.7896 | M60: ='Budget VS Actuals'!D58 -> 0.2490998
B61: =B12 -> 46174 | C61: ='Monthly Budget'!E13 -> 0.229 | D61: ='Monthly Actuals'!AF15 -> 0.241155 | J61: =B12 -> 46174 | K61: ='Budget VS Actuals'!E55 -> 272.74154 | L61: ='Budget VS Actuals'!E56 -> 351.0432 | M61: ='Budget VS Actuals'!E58 -> 0.28709105
B79: ="What this shows: actual EBITDA margin held near "&TEXT('Variance Analysis'!D10/'Variance Analysis'!D6,"0.0%")&" through Q1. April revenue was below budget, while stronger performance in May and June more than offset "&"the initial shortfall; EBITDA margin remained broadly stable because the derived monthly cost structure follows "&"the assumed quarterly allocation pattern, not because of an operational cost or revenue finding." -> What this shows: actual EBITDA margin held near 24.1% through Q1. April revenue was below budget, while stronger performance in May and June more than offset the initial shortfall; EBITDA margin remained broadly stable because the derived monthly cost structure follows the assumed quarterly allocation pattern, not because of an operational cost or revenue finding.
B80: ="What this shows: PAT beat budget by Rs "&TEXT('Variance Analysis'!E14,"#,##0")&" Cr for the quarter ("&TEXT('Variance Analysis'!F14,"+0.0%;-0.0%")&"), proportionally less than the "&TEXT('Variance Analysis'!F10,"0.0%")&" EBITDA beat, because the higher pre-tax profit also pushed the tax charge up "&TEXT('Variance Analysis'!F13,"0.0%")&" - normal flow-through, not a new issue." -> What this shows: PAT beat budget by Rs 104 Cr for the quarter (+11.9%), proportionally less than the 16.5% EBITDA beat, because the higher pre-tax profit also pushed the tax charge up 32.7% - normal flow-through, not a new issue.

Sheet Budget VS Forecast Dashboard
B2: ="Forecast Dashboard for FY27 (Jul-26 to Jun-27) - "&'Data Sheet'!B1 -> Forecast Dashboard for FY27 (Jul-26 to Jun-27) - NESTLE INDIA LTD
B3: Revenue | F3: EBITDA Margin | J3: EBITDA | N3: PAT
B4: ='Variance Analysis'!D18 -> 26852.104 | F4: ='Variance Analysis'!D22/'Variance Analysis'!D18 -> 0.22 | J4: ='Variance Analysis'!D22 -> 5907.4629 | N4: ='Variance Analysis'!D26 -> 3926.3308
B5: vs Budget | C5: ='Variance Analysis'!F18 -> 0.018181818 | D5: =IF(C5>0,"Increased","Decreased") -> Increased | F5: vs Budget | G5: =F4-('Variance Analysis'!C22/'Variance Analysis'!C18) -> -0.009 | H5: =IF(G5>0,"Increased","Decreased") -> Decreased | J5: vs Budget | K5: ='Variance Analysis'!F22 -> -0.021834061 | L5: =IF(K5>0,"Increased","Decreased") -> Decreased | N5: vs Budget | O5: ='Variance Analysis'!F26 -> -0.02427635 | P5: =IF(O5>0,"Increased","Decreased") -> Decreased
B6: Note: 'Forecast' is a model-generated projection built on its own growth/cost assumptions (Assumptions!E11, E15:E17) - a separate scenario from Budget, not a company estimate or guidance (see Assumptions!B36:B37).
B7: Revenue - FY Jul26-Jun27 Budget to Forecast (Rs Crore)
B8: Revenue
B9: Month | C9: Forecast | D9: Budget | E9: Variance | F9: Variance %
B10: ='Budget VS Forecast'!C4 -> 46204 | C10: ='Budget VS Forecast'!C8 -> 2054.7717 | D10: ='Budget VS Forecast'!C7 -> 2018.0794 | E10: =C10-D10 -> 36.692352 | F10: =IFERROR(E10/ABS(D10),0) -> 0.018181818
B11: ='Budget VS Forecast'!D4 -> 46235 | C11: ='Budget VS Forecast'!D8 -> 1959.4614 | D11: ='Budget VS Forecast'!D7 -> 1924.471 | E11: =C11-D11 -> 34.990382 | F11: =IFERROR(E11/ABS(D11),0) -> 0.018181818
B12: ='Budget VS Forecast'!E4 -> 46266 | C12: ='Budget VS Forecast'!E8 -> 2085.8783 | D12: ='Budget VS Forecast'!E7 -> 2048.6304 | E12: =C12-D12 -> 37.247826 | F12: =IFERROR(E12/ABS(D12),0) -> 0.018181818
B13: ='Budget VS Forecast'!F4 -> 46296 | C13: ='Budget VS Forecast'!F8 -> 2275.5036 | D13: ='Budget VS Forecast'!F7 -> 2234.8696 | E13: =C13-D13 -> 40.633992 | F13: =IFERROR(E13/ABS(D13),0) -> 0.018181818
B14: ='Budget VS Forecast'!G4 -> 46327 | C14: ='Budget VS Forecast'!G8 -> 1967.5963 | D14: ='Budget VS Forecast'!G7 -> 1932.4606 | E14: =C14-D14 -> 35.135648 | F14: =IFERROR(E14/ABS(D14),0) -> 0.018181818
B15: ='Budget VS Forecast'!H4 -> 46357 | C15: ='Budget VS Forecast'!H8 -> 2094.538 | D15: ='Budget VS Forecast'!H7 -> 2057.1355 | E15: =C15-D15 -> 37.402464 | F15: =IFERROR(E15/ABS(D15),0) -> 0.018181818
B16: ='Budget VS Forecast'!I4 -> 46388 | C16: ='Budget VS Forecast'!I8 -> 2284.9505 | D16: ='Budget VS Forecast'!I7 -> 2244.1478 | E16: =C16-D16 -> 40.802688 | F16: =IFERROR(E16/ABS(D16),0) -> 0.018181818
B17: ='Budget VS Forecast'!J4 -> 46419 | C17: ='Budget VS Forecast'!J8 -> 2342.8327 | D17: ='Budget VS Forecast'!J7 -> 2300.9964 | E17: =C17-D17 -> 41.836298 | F17: =IFERROR(E17/ABS(D17),0) -> 0.018181818
B18: ='Budget VS Forecast'!K4 -> 46447 | C18: ='Budget VS Forecast'!K8 -> 2493.9832 | D18: ='Budget VS Forecast'!K7 -> 2449.4478 | E18: =C18-D18 -> 44.535414 | F18: =IFERROR(E18/ABS(D18),0) -> 0.018181818
B19: ='Budget VS Forecast'!L4 -> 46478 | C19: ='Budget VS Forecast'!L8 -> 2720.7089 | D19: ='Budget VS Forecast'!L7 -> 2672.1248 | E19: =C19-D19 -> 48.584088 | F19: =IFERROR(E19/ABS(D19),0) -> 0.018181818
B20: ='Budget VS Forecast'!M4 -> 46508 | C20: ='Budget VS Forecast'!M8 -> 2214.5041 | D20: ='Budget VS Forecast'!M7 -> 2174.9594 | E20: =C20-D20 -> 39.544716 | F20: =IFERROR(E20/ABS(D20),0) -> 0.018181818
B21: ='Budget VS Forecast'!N4 -> 46539 | C21: ='Budget VS Forecast'!N8 -> 2357.3753 | D21: ='Budget VS Forecast'!N7 -> 2315.2793 | E21: =C21-D21 -> 42.095988 | F21: =IFERROR(E21/ABS(D21),0) -> 0.018181818
B23: Revenue exceeded budget — driven by the higher revenue growth assumption used in the Forecast (12% p.a.) versus the Budget (10% p.a.), a modelling choice on the Assumptions sheet rather than a confirmed operational trend. Variance between the Budget and the Forecast is approximately +1.82%.
B25: EBITDA Bridge - FY Jul26-Jun27 Budget to Forecast (Rs Crore)
B27: Category | C27: Type | D27: Net Impact (Rs Cr) | E27: Running Total | F27: Base | G27: Increase | H27: Decrease | I27: Total
B28: FY Budget EBITDA | C28: Total | D28: ='Variance Analysis'!C22 -> 6039.3259 | E28: =D28 -> 6039.3259 | F28: =0 -> 0 | G28: =IF(C28="Increase",MAX(D28,0),0) -> 0 | H28: =IF(C28="Decrease",MAX(-D28,0),0) -> 0 | I28: =IF(C28="Total",D28,0) -> 6039.3259
B29: Revenue Variance | C29: Increase | D29: ='Variance Analysis'!D18-'Variance Analysis'!C18 -> 479.50186 | E29: =IF(C29="Total",D29,E28+D29) -> 6518.8277 | F29: =IF(C29="Total",0,MIN(E28,E29)) -> 6039.3259 | G29: =IF(C29="Increase",MAX(D29,0),0) -> 479.50186 | H29: =IF(C29="Decrease",MAX(-D29,0),0) -> 0 | I29: =IF(C29="Total",D29,0) -> 0
B30: COGS Impact | C30: Decrease | D30: =-('Variance Analysis'!D19-'Variance Analysis'!C19) -> -374.01145 | E30: =IF(C30="Total",D30,E29+D30) -> 6144.8163 | F30: =IF(C30="Total",0,MIN(E29,E30)) -> 6144.8163 | G30: =IF(C30="Increase",MAX(D30,0),0) -> 0 | H30: =IF(C30="Decrease",MAX(-D30,0),0) -> 374.01145 | I30: =IF(C30="Total",D30,0) -> 0
B31: Employee Cost Impact | C31: Decrease | D31: =-('Variance Analysis'!D20-'Variance Analysis'!C20) -> 4.7950186 | E31: =IF(C31="Total",D31,E30+D31) -> 6149.6113 | F31: =IF(C31="Total",0,MIN(E30,E31)) -> 6144.8163 | G31: =IF(C31="Increase",MAX(D31,0),0) -> 0 | H31: =IF(C31="Decrease",MAX(-D31,0),0) -> 0 | I31: =IF(C31="Total",D31,0) -> 0
B32: Other Opex Impact | C32: Decrease | D32: =-('Variance Analysis'!D21-'Variance Analysis'!C21) -> -242.14844 | E32: =IF(C32="Total",D32,E31+D32) -> 5907.4629 | F32: =IF(C32="Total",0,MIN(E31,E32)) -> 5907.4629 | G32: =IF(C32="Increase",MAX(D32,0),0) -> 0 | H32: =IF(C32="Decrease",MAX(-D32,0),0) -> 242.14844 | I32: =IF(C32="Total",D32,0) -> 0
B33: FY Forecast EBITDA | C33: Total | D33: ='Variance Analysis'!D22 -> 5907.4629 | E33: =IF(C33="Total",D33,E32+D33) -> 5907.4629 | F33: =IF(C33="Total",0,MIN(E32,E33)) -> 0 | G33: =IF(C33="Increase",MAX(D33,0),0) -> 0 | H33: =IF(C33="Decrease",MAX(-D33,0),0) -> 0 | I33: =IF(C33="Total",D33,0) -> 5907.4629
B44: ="What this shows: full-year forecast EBITDA comes in at Rs "&TEXT('Variance Analysis'!D22,"#,##0")&" Cr versus a Rs "&TEXT('Variance Analysis'!C22,"#,##0")&" Cr budget, a "&TEXT('Variance Analysis'!F22,"+0.0%;-0.0%")&" shortfall. Forecast revenue is actually Rs "&TEXT('Variance Analysis'!D18-'Variance Analysis'!C18,"#,##0")&" Cr above budget, but COGS, employee cost and other opex are all forecast to run further ahead of budget still - "&"cost growth is outpacing revenue growth in this scenario, the opposite pattern from the Q1 actuals." -> What this shows: full-year forecast EBITDA comes in at Rs 5,907 Cr versus a Rs 6,039 Cr budget, a -2.2% shortfall. Forecast revenue is actually Rs 480 Cr above budget, but COGS, employee cost and other opex are all forecast to run further ahead of budget still - cost growth is outpacing revenue growth in this scenario, the opposite pattern from the Q1 actuals.
B46: Cost Structure - FY Budget vs Forecast (Rs Crore)
B48: Cost Line | C48: Budget | D48: Forecast | E48: Variance %
B49: COGS | C49: ='Variance Analysis'!C19 -> 10232.57 | D49: ='Variance Analysis'!D19 -> 10606.581 | E49: ='Variance Analysis'!F19 -> 0.036551078
B50: Employee Cost | C50: ='Variance Analysis'!C20 -> 2690.0054 | D50: ='Variance Analysis'!D20 -> 2685.2104 | E50: ='Variance Analysis'!F20 -> -0.0017825312
B51: Other Operating Expenses | C51: ='Variance Analysis'!C21 -> 7410.7012 | D51: ='Variance Analysis'!D21 -> 7652.8496 | E51: ='Variance Analysis'!F21 -> 0.03267551
B64: ="What this shows: every cost line is forecast to exceed budget by roughly "&TEXT('Variance Analysis'!F19,"0.0%")&" - all three cost-ratio assumptions (Assumptions!E15:E17) were set slightly higher than Budget's, so this gap "&"is a modelling choice, not a bottom-up cost forecast." -> What this shows: every cost line is forecast to exceed budget by roughly 3.7% - all three cost-ratio assumptions (Assumptions!E15:E17) were set slightly higher than Budget's, so this gap is a modelling choice, not a bottom-up cost forecast.
B66: EBITDA Margin Trend - Budget vs Forecast (FY Jul26-Jun27)
B68: Month | C68: Budget Margin % | D68: Forecast Margin %
B69: ='Budget VS Forecast'!C4 -> 46204 | C69: ='Monthly Budget'!F13 -> 0.229 | D69: ='Rolling Forecast'!D14 -> 0.22
B70: ='Budget VS Forecast'!D4 -> 46235 | C70: ='Monthly Budget'!G13 -> 0.229 | D70: ='Rolling Forecast'!E14 -> 0.22
...

Sheet  Model>

Sheet Monthly Actuals
B2: ="Derived Monthly Actuals -"&'Data Sheet'!B1 -> Derived Monthly Actuals -NESTLE INDIA LTD
B3: Derived Monthly Actual - NOT company-reported. Allocated from Nestlé India's reported quarterly results (Data Sheet) using the monthly seasonality assumption on the Assumptions sheet.
B5: Month | C5: 45292 | D5: 45323 | E5: 45352 | F5: 45383 | G5: 45413 | H5: 45444 | I5: 45474 | J5: 45505 | K5: 45536 | L5: 45566 | M5: 45597 | N5: 45627 | O5: 45658 | P5: 45689 | Q5: 45717 | R5: 45748 | S5: 45778 | T5: 45809 | U5: 45839 | V5: 45870 | W5: 45901 | X5: 45931 | Y5: 45962 | Z5: 45992 | AA5: 46023 | AB5: 46054 | AC5: 46082 | AD5: 46113 | AE5: 46143 | AF5: 46174
B6: Reported Quarter (source) | C6: Q4 FY23-24 | D6: Q4 FY23-24 | E6: Q4 FY23-24 | F6: Q1 FY24-25 | G6: Q1 FY24-25 | H6: Q1 FY24-25 | I6: Q2 FY24-25 | J6: Q2 FY24-25 | K6: Q2 FY24-25 | L6: Q3 FY24-25 | M6: Q3 FY24-25 | N6: Q3 FY24-25 | O6: Q4 FY24-25 | P6: Q4 FY24-25 | Q6: Q4 FY24-25 | R6: Q1 FY25-26 | S6: Q1 FY25-26 | T6: Q1 FY25-26 | U6: Q2 FY25-26 | V6: Q2 FY25-26 | W6: Q2 FY25-26 | X6: Q3 FY25-26 | Y6: Q3 FY25-26 | Z6: Q3 FY25-26 | AA6: Q4 FY25-26 | AB6: Q4 FY25-26 | AC6: Q4 FY25-26 | AD6: Q1 FY26-27 | AE6: Q1 FY26-27 | AF6: Q1 FY26-27
B8: Income Statement (Derived Monthly Actual )
B9: Revenue | C9: ='Data Sheet'!B42*Assumptions!$E$4 -> 1632.9529 | D9: ='Data Sheet'!B42*Assumptions!$E$5 -> 1738.3047 | E9: ='Data Sheet'!B42*Assumptions!$E$6 -> 1896.3324 | F9: ='Data Sheet'!C42*Assumptions!$E$4 -> 1492.3245 | G9: ='Data Sheet'!C42*Assumptions!$E$5 -> 1588.6035 | H9: ='Data Sheet'!C42*Assumptions!$E$6 -> 1733.022 | I9: ='Data Sheet'!D42*Assumptions!$E$4 -> 1582.24 | J9: ='Data Sheet'!D42*Assumptions!$E$5 -> 1684.32 | K9: ='Data Sheet'!D42*Assumptions!$E$6 -> 1837.44 | L9: ='Data Sheet'!E42*Assumptions!$E$4 -> 1481.7163 | M9: ='Data Sheet'!E42*Assumptions!$E$5 -> 1577.3109 | N9: ='Data Sheet'!E42*Assumptions!$E$6 -> 1720.7028 | O9: ='Data Sheet'!F42*Assumptions!$E$4 -> 1706.2028 | P9: ='Data Sheet'!F42*Assumptions!$E$5 -> 1816.2804 | Q9: ='Data Sheet'!F42*Assumptions!$E$6 -> 1981.3968 | R9: ='Data Sheet'!G42*Assumptions!$E$4 -> 1579.8096 | S9: ='Data Sheet'!G42*Assumptions!$E$5 -> 1681.7328 | T9: ='Data Sheet'!G42*Assumptions!$E$6 -> 1834.6176 | U9: ='Data Sheet'!H42*Assumptions!$E$4 -> 1749.5191 | V9: ='Data Sheet'!H42*Assumptions!$E$5 -> 1862.3913 | W9: ='Data Sheet'!H42*Assumptions!$E$6 -> 2031.6996 | X9: ='Data Sheet'!I42*Assumptions!$E$4 -> 1756.7824 | Y9: ='Data Sheet'!I42*Assumptions!$E$5 -> 1870.1232 | Z9: ='Data Sheet'!I42*Assumptions!$E$6 -> 2040.1344 | AA9: ='Data Sheet'!J42*Assumptions!$E$4 -> 2091.8149 | AB9: ='Data Sheet'!J42*Assumptions!$E$5 -> 2226.7707 | AC9: ='Data Sheet'!J42*Assumptions!$E$6 -> 2429.2044 | AD9: ='Data Sheet'!K42*Assumptions!$E$4 -> 1977.2358 | AE9: ='Data Sheet'!K42*Assumptions!$E$5 -> 2104.7994 | AF9: ='Data Sheet'!K42*Assumptions!$E$6 -> 2296.1448
B10: Total Operating Expenses | C10: ='Data Sheet'!B43*Assumptions!$E$4 -> 1214.4374 | D10: ='Data Sheet'!B43*Assumptions!$E$5 -> 1292.7882 | E10: ='Data Sheet'!B43*Assumptions!$E$6 -> 1410.3144 | F10: ='Data Sheet'!C43*Assumptions!$E$4 -> 1146.8822 | G10: ='Data Sheet'!C43*Assumptions!$E$5 -> 1220.8746 | H10: ='Data Sheet'!C43*Assumptions!$E$6 -> 1331.8632 | I10: ='Data Sheet'!D43*Assumptions!$E$4 -> 1220.2437 | J10: ='Data Sheet'!D43*Assumptions!$E$5 -> 1298.9691 | K10: ='Data Sheet'!D43*Assumptions!$E$6 -> 1417.0572 | L10: ='Data Sheet'!E43*Assumptions!$E$4 -> 1139.8824 | M10: ='Data Sheet'!E43*Assumptions!$E$5 -> 1213.4232 | N10: ='Data Sheet'!E43*Assumptions!$E$6 -> 1323.7344 | O10: ='Data Sheet'!F43*Assumptions!$E$4 -> 1275.8298 | P10: ='Data Sheet'!F43*Assumptions!$E$5 -> 1358.1414 | Q10: ='Data Sheet'!F43*Assumptions!$E$6 -> 1481.6088 | R10: ='Data Sheet'!G43*Assumptions!$E$4 -> 1238.7693 | S10: ='Data Sheet'!G43*Assumptions!$E$5 -> 1318.6899 | T10: ='Data Sheet'!G43*Assumptions!$E$6 -> 1438.5708 | U10: ='Data Sheet'!H43*Assumptions!$E$4 -> 1366.1607 | V10: ='Data Sheet'!H43*Assumptions!$E$5 -> 1454.3001 | W10: ='Data Sheet'!H43*Assumptions!$E$6 -> 1586.5092 | X10: ='Data Sheet'!I43*Assumptions!$E$4 -> 1384.4879 | Y10: ='Data Sheet'!I43*Assumptions!$E$5 -> 1473.8097 | Z10: ='Data Sheet'!I43*Assumptions!$E$6 -> 1607.7924 | AA10: ='Data Sheet'!J43*Assumptions!$E$4 -> 1542.6189 | AB10: ='Data Sheet'!J43*Assumptions!$E$5 -> 1642.1427 | AC10: ='Data Sheet'!J43*Assumptions!$E$6 -> 1791.4284 | AD10: ='Data Sheet'!K43*Assumptions!$E$4 -> 1500.4155 | AE10: ='Data Sheet'!K43*Assumptions!$E$5 -> 1597.2165 | AF10: ='Data Sheet'!K43*Assumptions!$E$6 -> 1742.418
B11: COGS / Material Cost | C11: =C10*Assumptions!$E$29 -> 601.14651 | D11: =D10*Assumptions!$E$29 -> 639.93016 | E11: =E10*Assumptions!$E$29 -> 698.10563 | F11: =F10*Assumptions!$E$29 -> 567.70669 | G11: =G10*Assumptions!$E$29 -> 604.33293 | H11: =H10*Assumptions!$E$29 -> 659.27228 | I11: =I10*Assumptions!$E$29 -> 604.02063 | J11: =J10*Assumptions!$E$29 -> 642.9897 | ... AF11: =AF10*Assumptions!$E$29 -> 862.49691
B12: Employee Cost | C12: =Assumptions!$E$30*C10 -> 160.30574 | D12: =Assumptions!$E$30*D10 -> 170.64804 | E12: =Assumptions!$E$30*E10 -> 186.1615 | F12: =Assumptions!$E$30*F10 -> 151.38845 | G12: =Assumptions!$E$30*G10 -> 161.15545 | H12: =Assumptions!$E$30*H10 -> 175.80594 | I12: =Assumptions!$E$30*I10 -> 161.07217 | J12: =Assumptions!$E$30*J10 -> 171.46392 | ... AF12: =Assumptions!$E$30*AF10 -> 229.99918
B13: Other Operating Expenses | C13: =C10*Assumptions!$E$31 -> 452.98515 | D13: =D10*Assumptions!$E$31 -> 482.21 | E13: =E10*Assumptions!$E$31 -> 526.04727 | F13: =F10*Assumptions!$E$31 -> 427.78706 | G13: =G10*Assumptions!$E$31 -> 455.38623 | H13: =H10*Assumptions!$E$31 -> 496.78497 | I13: =I10*Assumptions!$E$31 -> 455.1509 | J13: =J10*Assumptions!$E$31 -> 484.51547 | ... AF13: =AF10*Assumptions!$E$31 -> 649.92191
B14: EBITDA | C14: =C9-C10 -> 418.5155 | D14: =D9-D10 -> 445.5165 | E14: =E9-E10 -> 486.018 | F14: =F9-F10 -> 345.4423 | G14: =G9-G10 -> 367.7289 | H14: =H9-H10 -> 401.1588 | I14: =I9-I10 -> 361.9963 | J14: =J9-J10 -> 385.3509 | ... AF14: =AF9-AF10 -> 553.7268
B15: EBITDA Margin % | C15: =C14/C9 -> 0.25629368 | D15: =D14/D9 -> 0.25629368 | E15: =E14/E9 -> 0.25629368 | F15: =F14/F9 -> 0.23147935 | G15: =G14/G9 -> 0.23147935 | H15: =H14/H9 -> 0.23147935 | I15: =I14/I9 -> 0.22878723 | J15: =J14/J9 -> 0.22878723 | ... AF15: =AF14/AF9 -> 0.241155
B16: Other Income | C16: ='Data Sheet'!B44*Assumptions!$E$4 -> 11.4173 | D16: ='Data Sheet'!B44*Assumptions!$E$5 -> 12.1539 | E16: ='Data Sheet'!B44*Assumptions!$E$6 -> 13.2588 | F16: ='Data Sheet'!C44*Assumptions!$E$4 -> 12.1272 | G16: ='Data Sheet'!C44*Assumptions!$E$5 -> 12.9096 | H16: ='Data Sheet'!C44*Assumptions!$E$6 -> 14.0832 | I16: ='Data Sheet'!D44*Assumptions!$E$4 -> 92.2808 | J16: ='Data Sheet'!D44*Assumptions!$E$5 -> 98.2344 | K16: ='Data Sheet'!D44*Assumptions!$E$6 -> 107.1648 | L16: ='Data Sheet'!E44*Assumptions!$E$4 -> 1.3764 | M16: ='Data Sheet'!E44*Assumptions!$E$5 -> 1.4652 | N16: ='Data Sheet'!E44*Assumptions!$E$6 -> 1.5984 | O16: ='Data Sheet'!F44*Assumptions!$E$4 -> 2.821 | P16: ='Data Sheet'!F44*Assumptions!$E$5 -> 3.003 | Q16: ='Data Sheet'!F44*Assumptions!$E$6 -> 3.276 | R16: ='Data Sheet'!G44*Assumptions!$E$4 -> 1.2927 | S16: ='Data Sheet'!G44*Assumptions!$E$5 -> 1.3761 | T16: ='Data Sheet'!G44*Assumptions!$E$6 -> 1.5012 | U16: ='Data Sheet'!H44*Assumptions!$E$4 -> 0.5084 | V16: ='Data Sheet'!H44*Assumptions!$E$5 -> 0.5412 | W16: ='Data Sheet'!H44*Assumptions!$E$6 -> 0.5904 | X16: ='Data Sheet'!I44*Assumptions!$E$4 -> 52.6318 | Y16: ='Data Sheet'!I44*Assumptions!$E$5 -> 56.0274 | Z16: ='Data Sheet'!I44*Assumptions!$E$6 -> 61.1208 | AA16: ='Data Sheet'!J44*Assumptions!$E$4 -> -5.4932 | AB16: ='Data Sheet'!J44*Assumptions!$E$5 -> -5.8476 | AC16: ='Data Sheet'!J44*Assumptions!$E$6 -> -6.3792 | AD16: ='Data Sheet'!K44*Assumptions!$E$4 -> 5.0344 | AE16: ='Data Sheet'!K44*Assumptions!$E$5 -> 5.3592 | AF16: ='Data Sheet'!K44*Assumptions!$E$6 -> 5.8464
B17: Depreciation | C17: ='Data Sheet'!B45*Assumptions!$E$4 -> 34.131 | D17: ='Data Sheet'!B45*Assumptions!$E$5 -> 36.333 | E17: ='Data Sheet'!B45*Assumptions!$E$6 -> 39.636 | F17: ='Data Sheet'!C45*Assumptions!$E$4 -> 34.9401 | G17: ='Data Sheet'!C45*Assumptions!$E$5 -> 37.1943 | H17: ='Data Sheet'!C45*Assumptions!$E$6 -> 40.5756 | I17: ='Data Sheet'!D45*Assumptions!$E$4 -> 37.696 | J17: ='Data Sheet'!D45*Assumptions!$E$5 -> 40.128 | K17: ='Data Sheet'!D45*Assumptions!$E$6 -> 43.776 | L17: ='Data Sheet'!E45*Assumptions!$E$4 -> 46.5837 | M17: ='Data Sheet'!E45*Assumptions!$E$5 -> 49.5891 | N17: ='Data Sheet'!E45*Assumptions!$E$6 -> 54.0972 | O17: ='Data Sheet'!F45*Assumptions!$E$4 -> 48.1554 | P17: ='Data Sheet'!F45*Assumptions!$E$5 -> 51.2622 | Q17: ='Data Sheet'!F45*Assumptions!$E$6 -> 55.9224 | R17: ='Data Sheet'!G45*Assumptions!$E$4 -> 48.6514 | S17: ='Data Sheet'!G45*Assumptions!$E$5 -> 51.7902 | T17: ='Data Sheet'!G45*Assumptions!$E$6 -> 56.4984 | U17: ='Data Sheet'!H45*Assumptions!$E$4 -> 50.6385 | V17: ='Data Sheet'!H45*Assumptions!$E$5 -> 53.9055 | W17: ='Data Sheet'!H45*Assumptions!$E$6 -> 58.806 | X17: ='Data Sheet'!I45*Assumptions!$E$4 -> 54.0671 | Y17: ='Data Sheet'!I45*Assumptions!$E$5 -> 57.5553 | Z17: ='Data Sheet'!I45*Assumptions!$E$6 -> 62.7876 | AA17: ='Data Sheet'!J45*Assumptions!$E$4 -> 63.4043 | AB17: ='Data Sheet'!J45*Assumptions!$E$5 -> 67.4949 | AC17: ='Data Sheet'!J45*Assumptions!$E$6 -> 73.6308 | AD17: ='Data Sheet'!K45*Assumptions!$E$4 -> 58.218 | AE17: ='Data Sheet'!K45*Assumptions!$E$5 -> 61.974 | AF17: ='Data Sheet'!K45*Assumptions!$E$6 -> 67.608
B18: EBIT | C18: =C14-(C17)+C16 -> 395.8018 | D18: =D14-(D17)+D16 -> 421.3374 | E18: =E14-(E17)+E16 -> 459.6408 | F18: =F14-(F17)+F16 -> 322.6294 | G18: =G14-(G17)+G16 -> 343.4442 | H18: =H14-(H17)+H16 -> 374.6664 | I18: =I14-(I17)+I16 -> 416.5811 | J18: =J14-(J17)+J16 -> 443.4573 | ... AF18: =AF14-(AF17)+AF16 -> 491.9652
B19: Interest | C19: ='Data Sheet'!B46*Assumptions!$E$4 -> 8.122 | D19: ='Data Sheet'!B46*Assumptions!$E$5 -> 8.646 | E19: ='Data Sheet'!B46*Assumptions!$E$6 -> 9.432 | F19: ='Data Sheet'!C46*Assumptions!$E$4 -> 9.8208 | G19: ='Data Sheet'!C46*Assumptions!$E$5 -> 10.4544 | H19: ='Data Sheet'!C46*Assumptions!$E$6 -> 11.4048 | I19: ='Data Sheet'!D46*Assumptions!$E$4 -> 9.9882 | J19: ='Data Sheet'!D46*Assumptions!$E$5 -> 10.6326 | K19: ='Data Sheet'!D46*Assumptions!$E$6 -> 11.5992 | L19: ='Data Sheet'!E46*Assumptions!$E$4 -> 10.726 | M19: ='Data Sheet'!E46*Assumptions!$E$5 -> 11.418 | N19: ='Data Sheet'!E46*Assumptions!$E$6 -> 12.456 | O19: ='Data Sheet'!F46*Assumptions!$E$4 -> 11.625 | P19: ='Data Sheet'!F46*Assumptions!$E$5 -> 12.375 | Q19: ='Data Sheet'!F46*Assumptions!$E$6 -> 13.5 | R19: ='Data Sheet'!G46*Assumptions!$E$4 -> 14.5359 | S19: ='Data Sheet'!G46*Assumptions!$E$5 -> 15.4737 | T19: ='Data Sheet'!G46*Assumptions!$E$6 -> 16.8804 | U19: ='Data Sheet'!H46*Assumptions!$E$4 -> 14.3871 | V19: ='Data Sheet'!H46*Assumptions!$E$5 -> 15.3153 | W19: ='Data Sheet'!H46*Assumptions!$E$6 -> 16.7076 | X19: ='Data Sheet'!I46*Assumptions!$E$4 -> 8.7575 | Y19: ='Data Sheet'!I46*Assumptions!$E$5 -> 9.3225 | Z19: ='Data Sheet'!I46*Assumptions!$E$6 -> 10.17 | AA19: ='Data Sheet'!J46*Assumptions!$E$4 -> 11.3956 | AB19: ='Data Sheet'!J46*Assumptions!$E$5 -> 12.1308 | AC19: ='Data Sheet'!J46*Assumptions!$E$6 -> 13.2336 | AD19: ='Data Sheet'!K46*Assumptions!$E$4 -> 13.0758 | AE19: ='Data Sheet'!K46*Assumptions!$E$5 -> 13.9194 | AF19: ='Data Sheet'!K46*Assumptions!$E$6 -> 15.1848
B20: EBT | C20: =C18-C19 -> 387.6798 | D20: =D18-D19 -> 412.6914 | E20: =E18-E19 -> 450.2088 | F20: =F18-F19 -> 312.8086 | G20: =G18-G19 -> 332.9898 | H20: =H18-H19 -> 363.2616 | I20: =I18-I19 -> 406.5929 | J20: =J18-J19 -> 432.8247 | ... AF20: =AF18-AF19 -> 476.7804
B21: Tax | C21: ='Data Sheet'!B48*Assumptions!$E$4 -> 98.0871 | D21: ='Data Sheet'!B48*Assumptions!$E$5 -> 104.4153 | E21: ='Data Sheet'!B48*Assumptions!$E$6 -> 113.9076 | F21: ='Data Sheet'!C48*Assumptions!$E$4 -> 81.3626 | G21: ='Data Sheet'!C48*Assumptions!$E$5 -> 86.6118 | H21: ='Data Sheet'!C48*Assumptions!$E$6 -> 94.4856 | I21: ='Data Sheet'!D48*Assumptions!$E$4 -> 100.8213 | J21: ='Data Sheet'!D48*Assumptions!$E$5 -> 107.3259 | K21: ='Data Sheet'!D48*Assumptions!$E$6 -> 117.0828 | L21: ='Data Sheet'!E48*Assumptions!$E$4 -> 70.1003 | M21: ='Data Sheet'!E48*Assumptions!$E$5 -> 74.6229 | N21: ='Data Sheet'!E48*Assumptions!$E$6 -> 81.4068 | O21: ='Data Sheet'!F48*Assumptions!$E$4 -> 98.9365 | P21: ='Data Sheet'!F48*Assumptions!$E$5 -> 105.3195 | Q21: ='Data Sheet'!F48*Assumptions!$E$6 -> 114.894 | R21: ='Data Sheet'!G48*Assumptions!$E$4 -> 74.7844 | S21: ='Data Sheet'!G48*Assumptions!$E$5 -> 79.6092 | T21: ='Data Sheet'!G48*Assumptions!$E$6 -> 86.8464 | U21: ='Data Sheet'!H48*Assumptions!$E$4 -> 85.3492 | V21: ='Data Sheet'!H48*Assumptions!$E$5 -> 90.8556 | W21: ='Data Sheet'!H48*Assumptions!$E$6 -> 99.1152 | X21: ='Data Sheet'!I48*Assumptions!$E$4 -> 46.5031 | Y21: ='Data Sheet'!I48*Assumptions!$E$5 -> 49.5033 | Z21: ='Data Sheet'!I48*Assumptions!$E$6 -> 54.0036 | AA21: ='Data Sheet'!J48*Assumptions!$E$4 -> 123.5288 | AB21: ='Data Sheet'!J48*Assumptions!$E$5 -> 131.4984 | AC21: ='Data Sheet'!J48*Assumptions!$E$6 -> 143.4528 | AD21: ='Data Sheet'!K48*Assumptions!$E$4 -> 108.2737 | AE21: ='Data Sheet'!K48*Assumptions!$E$5 -> 115.2591 | AF21: ='Data Sheet'!K48*Assumptions!$E$6 -> 125.7372
B22: PAT | C22: =C20-C21 -> 289.5927 | D22: =D20-D21 -> 308.2761 | E22: =E20-E21 -> 336.3012 | F22: =F20-F21 -> 231.446 | G22: =G20-G21 -> 246.378 | H22: =H20-H21 -> 268.776 | I22: =I20-I21 -> 305.7716 | J22: =J20-J21 -> 325.4988 | ... AF22: =AF20-AF21 -> 351.0432
B23: PAT Margin % | C23: =C22/C9 -> 0.17734296 | D23: =D22/D9 -> 0.17734296 | E23: =E22/E9 -> 0.17734296 | F23: =F22/F9 -> 0.15509093 | G23: =G22/G9 -> 0.15509093 | H23: =H22/H9 -> 0.15509093 | I23: =I22/I9 -> 0.19325235 | J23: =J22/J9 -> 0.19325235 | ... AF23: =AF22/AF9 -> 0.15288374
B25: Last 12-Month Actuals
B26: Revenue (12-mo sum) | C26: =SUM(U9:AF9) -> 24436.62
B27: EBITDA (12-mo sum) | C27: =SUM(U14:AF14) -> 5747.32
B28: PAT (12-mo sum) | C28: =SUM(U22:AF22) -> 3860.49
B30: Model Checks — Quarterly Reconciliation (Derived Monthly Actuals must sum exactly to reported quarterly figures)
B31: Confirms SUM(Month 1 + Month 2 + Month 3) = Reported Quarter, for both Revenue and Total Operating Expenses. Any non-zero difference is flagged.
B33: Quarter | C33: Reported Revenue (Data Sheet) | D33: Sum of 3 Derived Months (Revenue) | E33: Difference | F33: Reported Total Opex (Data Sheet) | G33: Sum of 3 Derived Months (Opex) | H33: Difference | I33: Status
B34: Q4 FY23-24 | C34: ='Data Sheet'!B42 -> 5267.59 | D34: =SUM(C9:E9) -> 5267.59 | E34: =C34-D34 -> 0 | F34: ='Data Sheet'!B43 -> 3917.54 | G34: =SUM(C10:E10) -> 3917.54 | H34: =F34-G34 -> 0 | I34: =IF(AND(ABS(E34)<0.01,ABS(H34)<0.01),"OK","FLAG — CHECK") -> OK
B35: Q1 FY24-25 | C35: ='Data Sheet'!C42 -> 4813.95 | D35: =SUM(F9:H9) -> 4813.95 | E35: =C35-D35 -> 0 | F35: ='Data Sheet'!C43 -> 3699.62 | G35: =SUM(F10:H10) -> 3699.62 | H35: =F35-G35 -> 0 | I35: =IF(AND(ABS(E35)<0.01,ABS(H35)<0.01),"OK","FLAG — CHECK") -> OK
B36: Q2 FY24-25 | C36: ='Data Sheet'!D42 -> 5104 | D36: =SUM(I9:K9) -> 5104 | E36: =C36-D36 -> 0 | F36: ='Data Sheet'!D43 -> 3936.27 | G36: =SUM(I10:K10) -> 3936.27 | H36: =F36-G36 -> 0 | I36: =IF(AND(ABS(E36)<0.01,ABS(H36)<0.01),"OK","FLAG — CHECK") -> OK
B37: Q3 FY24-25 | C37: ='Data Sheet'!E42 -> 4779.73 | D37: =SUM(L9:N9) -> 4779.73 | E37: =C37-D37 -> 0 | F37: ='Data Sheet'!E43 -> 3677.04 | G37: =SUM(L10:N10) -> 3677.04 | H37: =F37-G37 -> 0 | I37: =IF(AND(ABS(E37)<0.01,ABS(H37)<0.01),"OK","FLAG — CHECK") -> OK
B38: Q4 FY24-25 | C38: ='Data Sheet'!F42 -> 5503.88 | D38: =SUM(O9:Q9) -> 5503.88 | E38: =C38-D38 -> 0 | F38: ='Data Sheet'!F43 -> 4115.58 | G38: =SUM(O10:Q10) -> 4115.58 | H38: =F38-G38 -> 0 | I38: =IF(AND(ABS(E38)<0.01,ABS(H38)<0.01),"OK","FLAG — CHECK") -> OK
B39: Q1 FY25-26 | C39: ='Data Sheet'!G42 -> 5096.16 | D39: =SUM(R9:T9) -> 5096.16 | E39: =C39-D39 -> 0 | F39: ='Data Sheet'!G43 -> 3996.03 | G39: =SUM(R10:T10) -> 3996.03 | H39: =F39-G39 -> 0 | I39: =IF(AND(ABS(E39)<0.01,ABS(H39)<0.01),"OK","FLAG — CHECK") -> OK
B40: Q2 FY25-26 | C40: ='Data Sheet'!H42 -> 5643.61 | D40: =SUM(U9:W9) -> 5643.61 | E40: =C40-D40 -> 0 | F40: ='Data Sheet'!H43 -> 4406.97 | G40: =SUM(U10:W10) -> 4406.97 | H40: =F40-G40 -> 0 | I40: =IF(AND(ABS(E40)<0.01,ABS(H40)<0.01),"OK","FLAG — CHECK") -> OK
B41: Q3 FY25-26 | C41: ='Data Sheet'!I42 -> 5667.04 | D41: =SUM(X9:Z9) -> 5667.04 | E41: =C41-D41 -> 0 | F41: ='Data Sheet'!I43 -> 4466.09 | G41: =SUM(X10:Z10) -> 4466.09 | H41: =F41-G41 -> 0 | I41: =IF(AND(ABS(E41)<0.01,ABS(H41)<0.01),"OK","FLAG — CHECK") -> OK
B42: Q4 FY25-26 | C42: ='Data Sheet'!J42 -> 6747.79 | D42: =SUM(AA9:AC9) -> 6747.79 | E42: =C42-D42 -> 0 | F42: ='Data Sheet'!J43 -> 4976.19 | G42: =SUM(AA10:AC10) -> 4976.19 | H42: =F42-G42 -> 0 | I42: =IF(AND(ABS(E42)<0.01,ABS(H42)<0.01),"OK","FLAG — CHECK") -> OK
B43: Q1 FY26-27 | C43: ='Data Sheet'!K42 -> 6378.18 | D43: =SUM(AD9:AF9) -> 6378.18 | E43: =C43-D43 -> 0 | F43: ='Data Sheet'!K43 -> 4840.05 | G43: =SUM(AD10:AF10) -> 4840.05 | H43: =F43-G43 -> 0 | I43: =IF(AND(ABS(E43)<0.01,ABS(H43)<0.01),"OK","FLAG — CHECK") -> OK
B45: Overall Reconciliation Status | C45: =IF(COUNTIF(I34:I43,"OK")=COUNTA(I34:I43),"ALL QUARTERS RECONCILE","REVIEW FLAGGED QUARTERS") -> ALL QUARTERS RECONCILE

Sheet Monthly Budget
B2: ="Monthly Budget -"&'Data Sheet'!B1 -> Monthly Budget -NESTLE INDIA LTD
B4: Month | C4: 46113 | D4: 46143 | E4: 46174 | F4: 46204 | G4: 46235 | H4: 46266 | I4: 46296 | J4: 46327 | K4: 46357 | L4: 46388 | M4: 46419 | N4: 46447 | O4: 46478 | P4: 46508 | Q4: 46539
B6: Monthly Budget (₹ Crore)
B7: Revenue Budget | C7: ='Monthly Actuals'!Q$9*(1+Assumptions!$D$11) -> 2179.5365 | D7: ='Monthly Actuals'!R$9*(1+Assumptions!$D$11) -> 1737.7906 | E7: ='Monthly Actuals'!S$9*(1+Assumptions!$D$11) -> 1849.9061 | F7: ='Monthly Actuals'!T$9*(1+Assumptions!$D$11) -> 2018.0794 | G7: ='Monthly Actuals'!U$9*(1+Assumptions!$D$11) -> 1924.471 | H7: ='Monthly Actuals'!V$9*(1+Assumptions!$D$11) -> 2048.6304 | I7: ='Monthly Actuals'!W$9*(1+Assumptions!$D$11) -> 2234.8696 | J7: ='Monthly Actuals'!X$9*(1+Assumptions!$D$11) -> 1932.4606 | ... Q7: ='Monthly Actuals'!AE$9*(1+Assumptions!$D$11) -> 2315.2793
B8: Total Operating Expenses Budget | C8: =C9+C10+C11 -> 1680.4226 | D8: =D9+D10+D11 -> 1339.8365 | E8: =E9+E10+E11 -> 1426.2776 | F8: =F9+F10+F11 -> 1555.9392 | G8: =G9+G10+G11 -> 1483.7671 | H8: =H9+H10+H11 -> 1579.4941 | I8: =I9+I10+I11 -> 1723.0844 | J8: =J9+J10+J11 -> 1489.9272 | ... Q8: =Q9+Q10+Q11 -> 1785.0804
B9: COGS Budget | C9: =C7*Assumptions!$D$15 -> 845.66015 | D9: =D7*Assumptions!$D$15 -> 674.26274 | E9: =E7*Assumptions!$D$15 -> 717.76356 | F9: =F7*Assumptions!$D$15 -> 783.01479 | G9: =G7*Assumptions!$D$15 -> 746.69475 | H9: =H7*Assumptions!$D$15 -> 794.86861 | I9: =I7*Assumptions!$D$15 -> 867.12939 | J9: =J7*Assumptions!$D$15 -> 749.79473 | ... Q9: =Q7*Assumptions!$D$15 -> 898.32838
B10: Employee Cost Budget | C10: =C7*Assumptions!$D$16 -> 222.31272 | D10: =D7*Assumptions!$D$16 -> 177.25464 | E10: =E7*Assumptions!$D$16 -> 188.69042 | F10: =F7*Assumptions!$D$16 -> 205.84409 | G10: =G7*Assumptions!$D$16 -> 196.29604 | H10: =H7*Assumptions!$D$16 -> 208.9603 | I10: =I7*Assumptions!$D$16 -> 227.9567 | J10: =J7*Assumptions!$D$16 -> 197.11099 | ... Q10: =Q7*Assumptions!$D$16 -> 236.15849
B11: Other Opex Budget | C11: =C7*Assumptions!$D$17 -> 612.44975 | D11: =D7*Assumptions!$D$17 -> 488.31915 | E11: =E7*Assumptions!$D$17 -> 519.82361 | F11: =F7*Assumptions!$D$17 -> 567.0803 | G11: =G7*Assumptions!$D$17 -> 540.77635 | H11: =H7*Assumptions!$D$17 -> 575.66515 | I11: =I7*Assumptions!$D$17 -> 627.99835 | J11: =J7*Assumptions!$D$17 -> 543.02144 | ... Q11: =Q7*Assumptions!$D$17 -> 650.59349
B12: EBITDA Budget | C12: =C7-C8 -> 499.11385 | D12: =D7-D8 -> 397.95404 | E12: =E7-E8 -> 423.62849 | F12: =F7-F8 -> 462.14017 | G12: =G7-G8 -> 440.70386 | H12: =H7-H8 -> 469.13637 | I12: =I7-I8 -> 511.78513 | J12: =J7-J8 -> 442.53349 | ... Q12: =Q7-Q8 -> 530.19897
B13: EBITDA Margin % | C13: =C12/C7 -> 0.229 | D13: =D12/D7 -> 0.229 | E13: =E12/E7 -> 0.229 | F13: =F12/F7 -> 0.229 | G13: =G12/G7 -> 0.229 | H13: =H12/H7 -> 0.229 | I13: =I12/I7 -> 0.229 | J13: =J12/J7 -> 0.229 | ... Q13: =Q12/Q7 -> 0.229
B14: Other Income Budget | C14: =C7*Assumptions!$D$24 -> 14.166987 | D14: =D7*Assumptions!$D$24 -> 11.295639 | E14: =E7*Assumptions!$D$24 -> 12.02439 | F14: =F7*Assumptions!$D$24 -> 13.117516 | G14: =G7*Assumptions!$D$24 -> 12.509062 | H14: =H7*Assumptions!$D$24 -> 13.316098 | I14: =I7*Assumptions!$D$24 -> 14.526652 | J14: =J7*Assumptions!$D$24 -> 12.560994 | ... Q14: =Q7*Assumptions!$D$24 -> 15.049316
B15: Depreciation Budget | C15: ='Monthly Actuals'!R$17*(1+Assumptions!$D$22) -> 53.711146 | D15: ='Monthly Actuals'!S$17*(1+Assumptions!$D$22) -> 57.176381 | E15: ='Monthly Actuals'!T$17*(1+Assumptions!$D$22) -> 62.374234 | F15: ='Monthly Actuals'!U$17*(1+Assumptions!$D$22) -> 55.904904 | G15: ='Monthly Actuals'!V$17*(1+Assumptions!$D$22) -> 59.511672 | H15: ='Monthly Actuals'!W$17*(1+Assumptions!$D$22) -> 64.921824 | I15: ='Monthly Actuals'!X$17*(1+Assumptions!$D$22) -> 59.690078 | J15: ='Monthly Actuals'!Y$17*(1+Assumptions!$D$22) -> 63.541051 | ... Q15: ='Monthly Actuals'!AF$17*(1+Assumptions!$D$22) -> 74.639232
B16: EBIT Budget | C16: =C12-C15+C14 -> 459.5697 | D16: =D12-D15+D14 -> 352.0733 | E16: =E12-E15+E14 -> 373.27865 | F16: =F12-F15+F14 -> 419.35279 | G16: =G12-G15+G14 -> 393.70125 | H16: =H12-H15+H14 -> 417.53064 | I16: =I12-I15+I14 -> 466.6217 | J16: =J12-J15+J14 -> 391.55343 | ... Q16: =Q12-Q15+Q14 -> 470.60905
B17: Interest Budget | C17: ='Monthly Actuals'!R$19*(1+Assumptions!$D$23) -> 15.626092 | D17: ='Monthly Actuals'!S$19*(1+Assumptions!$D$23) -> 16.634228 | E17: ='Monthly Actuals'!T$19*(1+Assumptions!$D$23) -> 18.14643 | F17: ='Monthly Actuals'!U$19*(1+Assumptions!$D$23) -> 15.466132 | G17: ='Monthly Actuals'!V$19*(1+Assumptions!$D$23) -> 16.463947 | H17: ='Monthly Actuals'!W$19*(1+Assumptions!$D$23) -> 17.96067 | I17: ='Monthly Actuals'!X$19*(1+Assumptions!$D$23) -> 9.4143125 | J17: ='Monthly Actuals'!Y$19*(1+Assumptions!$D$23) -> 10.021687 | ... Q17: ='Monthly Actuals'!AF$19*(1+Assumptions!$D$23) -> 16.32366
B18: PBT Budget | C18: =C16-C17 -> 443.9436 | D18: =D16-D17 -> 335.43907 | E18: =E16-E17 -> 355.13222 | F18: =F16-F17 -> 403.88665 | G18: =G16-G17 -> 377.2373 | H18: =H16-H17 -> 399.56997 | I18: =I16-I17 -> 457.20739 | J18: =J16-J17 -> 381.53174 | ... Q18: =Q16-Q17 -> 454.28539
B19: Tax Budget | C19: =C18*Assumptions!$D$25 -> 102.99492 | D19: =D18*Assumptions!$D$25 -> 77.821864 | E19: =E18*Assumptions!$D$25 -> 82.390675 | F19: =F18*Assumptions!$D$25 -> 93.701703 | G19: =G18*Assumptions!$D$25 -> 87.519054 | H19: =H18*Assumptions!$D$25 -> 92.700234 | I19: =I18*Assumptions!$D$25 -> 106.07211 | J19: =J18*Assumptions!$D$25 -> 88.515364 | ... Q19: =Q18*Assumptions!$D$25 -> 105.39421
B20: PAT Budget | C20: =C18-C19 -> 340.94869 | D20: =D18-D19 -> 257.6172 | E20: =E18-E19 -> 272.74154 | F20: =F18-F19 -> 310.18495 | G20: =G18-G19 -> 289.71825 | H20: =H18-H19 -> 306.86974 | I20: =I18-I19 -> 351.13528 | J20: =J18-J19 -> 293.01638 | ... Q20: =Q18-Q19 -> 348.89118
B21: PAT Margin % | C21: =C20/C7 -> 0.15643174 | D21: =D20/D7 -> 0.1482441 | E21: =E20/E7 -> 0.14743535 | F21: =F20/F7 -> 0.15370305 | G21: =G20/G7 -> 0.15054436 | H21: =H20/H7 -> 0.14979263 | I21: =I20/I7 -> 0.15711668 | J21: =J20/J7 -> 0.15162864 | ... Q21: =Q20/Q7 -> 0.15069075
B22: 12-Month Budget (Jul-26 to Jun-27)
B23: Revenue (12-mo sum) | C23: =SUM(F7:Q7) -> 26372.602
B24: EBITDA (12-mo sum) | C24: =SUM(F12:Q12) -> 6039.3259
B25: PAT (12-mo sum) | C25: =SUM(F20:Q20) -> 4024.0193

Sheet Rolling Forecast
B2: ="Rolling Forecast -"&'Data Sheet'!B1 -> Rolling Forecast -NESTLE INDIA LTD
B3: Framework: 12-Month Forward Forecast (rolls forward from the latest Derived Monthly Actual using the Forecast growth/cost assumptions on the Assumptions sheet, Section B-D, Forecast column). This is a single forward-projection window refreshed by advancing the base month — not a fully automated, continuously-rolling multi-scenario engine.
B4: Month | C4: 46174 | D4: 46204 | E4: 46235 | F4: 46266 | G4: 46296 | H4: 46327 | I4: 46357 | J4: 46388 | K4: 46419 | L4: 46447 | M4: 46478 | N4: 46508 | O4: 46539
C5: Actual (Derived) | D5: Forecast | E5: Forecast | F5: Forecast | G5: Forecast | H5: Forecast | I5: Forecast | J5: Forecast | K5: Forecast | L5: Forecast | M5: Forecast | N5: Forecast | O5: Forecast
B7: 12-Month Rolling Forecast (₹ Crore)
B8: Revenue | C8: ='Monthly Actuals'!AF9 -> 2296.1448 | D8: ='Monthly Actuals'!T$9*(1+Assumptions!$E$11) -> 2054.7717 | E8: ='Monthly Actuals'!U$9*(1+Assumptions!$E$11) -> 1959.4614 | F8: ='Monthly Actuals'!V$9*(1+Assumptions!$E$11) -> 2085.8783 | G8: ='Monthly Actuals'!W$9*(1+Assumptions!$E$11) -> 2275.5036 | H8: ='Monthly Actuals'!X$9*(1+Assumptions!$E$11) -> 1967.5963 | I8: ='Monthly Actuals'!Y$9*(1+Assumptions!$E$11) -> 2094.538 | J8: ='Monthly Actuals'!Z$9*(1+Assumptions!$E$11) -> 2284.9505 | K8: ='Monthly Actuals'!AA$9*(1+Assumptions!$E$11) -> 2342.8327 | ... O8: ='Monthly Actuals'!AE$9*(1+Assumptions!$E$11) -> 2357.3753
B9: Total Operating Expenses | C9: ='Monthly Actuals'!AF10 -> 1742.418 | D9: =D10+D11+D12 -> 1602.7219 | E9: =E10+E11+E12 -> 1528.3799 | F9: =F10+F11+F12 -> 1626.985 | G9: =G10+G11+G12 -> 1774.8928 | H9: =H10+H11+H12 -> 1534.7251 | I9: =I10+I11+I12 -> 1633.7396 | J9: =J10+J11+J12 -> 1782.2614 | K9: =K10+K11+K12 -> 1827.4095 | ... O9: =O10+O11+O12 -> 1838.7528
B10: COGS | C10: ='Monthly Actuals'!AF11 -> 862.49691 | D10: =D8*Assumptions!$E$15 -> 811.63483 | E10: =E8*Assumptions!$E$15 -> 773.98725 | F10: =F8*Assumptions!$E$15 -> 823.92191 | G10: =G8*Assumptions!$E$15 -> 898.8239 | H10: =H8*Assumptions!$E$15 -> 777.20053 | I10: =I8*Assumptions!$E$15 -> 827.3425 | J10: =J8*Assumptions!$E$15 -> 902.55546 | K10: =K8*Assumptions!$E$15 -> 925.41891 | ... O10: =O8*Assumptions!$E$15 -> 931.16325
B11: Employee Cost | C11: ='Monthly Actuals'!AF12 -> 229.99918 | D11: =D8*Assumptions!$E$16 -> 205.47717 | E11: =E8*Assumptions!$E$16 -> 195.94614 | F11: =F8*Assumptions!$E$16 -> 208.58783 | G11: =G8*Assumptions!$E$16 -> 227.55036 | H11: =H8*Assumptions!$E$16 -> 196.75963 | I11: =I8*Assumptions!$E$16 -> 209.4538 | J11: =J8*Assumptions!$E$16 -> 228.49505 | K11: =K8*Assumptions!$E$16 -> 234.28327 | ... O11: =O8*Assumptions!$E$16 -> 235.73753
B12: Other Opex | C12: ='Monthly Actuals'!AF13 -> 649.92191 | D12: =D8*Assumptions!$E$17 -> 585.60994 | E12: =E8*Assumptions!$E$17 -> 558.4465 | F12: =F8*Assumptions!$E$17 -> 594.4753 | G12: =G8*Assumptions!$E$17 -> 648.51851 | H12: =H8*Assumptions!$E$17 -> 560.76494 | I12: =I8*Assumptions!$E$17 -> 596.94333 | J12: =J8*Assumptions!$E$17 -> 651.2109 | K12: =K8*Assumptions!$E$17 -> 667.70732 | ... O12: =O8*Assumptions!$E$17 -> 671.85197
B13: EBITDA | C13: ='Monthly Actuals'!AF14 -> 553.7268 | D13: =D8-D9 -> 452.04978 | E13: =E8-E9 -> 431.08151 | F13: =F8-F9 -> 458.89322 | G13: =G8-G9 -> 500.61078 | H13: =H8-H9 -> 432.87118 | I13: =I8-I9 -> 460.79836 | J13: =J8-J9 -> 502.68912 | K13: =K8-K9 -> 515.42319 | ... O13: =O8-O9 -> 518.62257
B14: EBITDA Margin % | C14: =C13/C8 -> 0.241155 | D14: =D13/D8 -> 0.22 | E14: =E13/E8 -> 0.22 | F14: =F13/F8 -> 0.22 | G14: =G13/G8 -> 0.22 | H14: =H13/H8 -> 0.22 | I14: =I13/I8 -> 0.22 | J14: =J13/J8 -> 0.22 | ... O14: =O13/O8 -> 0.22
B15: Other Income | C15: ='Monthly Actuals'!AF16 -> 5.8464 | D15: =D8*Assumptions!$E$24 -> 14.383402 | E15: =E8*Assumptions!$E$24 -> 13.71623 | F15: =F8*Assumptions!$E$24 -> 14.601148 | G15: =G8*Assumptions!$E$24 -> 15.928525 | H15: =H8*Assumptions!$E$24 -> 13.773174 | I15: =I8*Assumptions!$E$24 -> 14.661766 | J15: =J8*Assumptions!$E$24 -> 15.994654 | K15: =K8*Assumptions!$E$24 -> 16.399829 | ... O15: =O8*Assumptions!$E$24 -> 16.501627
B16: Depreciation | C16: ='Monthly Actuals'!AF17 -> 67.608 | D16: ='Monthly Actuals'!T$17*(1+Assumptions!$E$22) -> 62.430732 | E16: ='Monthly Actuals'!U$17*(1+Assumptions!$E$22) -> 55.955542 | F16: ='Monthly Actuals'!V$17*(1+Assumptions!$E$22) -> 59.565578 | G16: ='Monthly Actuals'!W$17*(1+Assumptions!$E$22) -> 64.98063 | H16: ='Monthly Actuals'!X$17*(1+Assumptions!$E$22) -> 59.744145 | I16: ='Monthly Actuals'!Y$17*(1+Assumptions!$E$22) -> 63.598607 | J16: ='Monthly Actuals'!Z$17*(1+Assumptions!$E$22) -> 69.380298 | K16: ='Monthly Actuals'!AA$17*(1+Assumptions!$E$22) -> 70.061751 | ... O16: ='Monthly Actuals'!AE$17*(1+Assumptions!$E$22) -> 68.48127
B17: EBIT | C17: ='Monthly Actuals'!AF18 -> 491.9652 | D17: =D13+D15-D16 -> 404.00245 | E17: =E13+E15-E16 -> 388.84219 | F17: =F13+F15-F16 -> 413.92879 | G17: =G13+G15-G16 -> 451.55868 | H17: =H13+H15-H16 -> 386.90021 | I17: =I13+I15-I16 -> 411.86152 | J17: =J13+J15-J16 -> 449.30347 | K17: =K13+K15-K16 -> 461.76127 | ... O17: =O13+O15-O16 -> 466.64293
B18: Interest | C18: ='Monthly Actuals'!AF19 -> 15.1848 | D18: ='Monthly Actuals'!T$19*(1+Assumptions!$E$23) -> 18.315234 | E18: ='Monthly Actuals'!U$19*(1+Assumptions!$E$23) -> 15.610003 | F18: ='Monthly Actuals'!V$19*(1+Assumptions!$E$23) -> 16.6171 | G18: ='Monthly Actuals'!W$19*(1+Assumptions!$E$23) -> 18.127746 | H18: ='Monthly Actuals'!X$19*(1+Assumptions!$E$23) -> 9.5018875 | I18: ='Monthly Actuals'!Y$19*(1+Assumptions!$E$23) -> 10.114912 | J18: ='Monthly Actuals'!Z$19*(1+Assumptions!$E$23) -> 11.03445 | K18: ='Monthly Actuals'!AA$19*(1+Assumptions!$E$23) -> 12.364226 | ... O18: ='Monthly Actuals'!AE$19*(1+Assumptions!$E$23) -> 15.102549
B19: EBT | C19: ='Monthly Actuals'!AF20 -> 476.7804 | D19: =D17-D18 -> 385.68721 | E19: =E17-E18 -> 373.23219 | F19: =F17-F18 -> 397.31169 | G19: =G17-G18 -> 433.43093 | H19: =H17-H18 -> 377.39832 | I19: =I17-I18 -> 401.7466 | J19: =J17-J18 -> 438.26902 | K19: =K17-K18 -> 449.39704 | ... O19: =O17-O18 -> 451.54038
B20: Tax | C20: ='Monthly Actuals'!AF21 -> 125.7372 | D20: =D19*Assumptions!$E$25 -> 90.636495 | E20: =E19*Assumptions!$E$25 -> 87.709565 | F20: =F19*Assumptions!$E$25 -> 93.368246 | G20: =G19*Assumptions!$E$25 -> 101.85627 | H20: =H19*Assumptions!$E$25 -> 88.688606 | I20: =I19*Assumptions!$E$25 -> 94.410452 | J20: =J19*Assumptions!$E$25 -> 102.99322 | K20: =K19*Assumptions!$E$25 -> 105.60831 | ... O20: =O19*Assumptions!$E$25 -> 106.11199
B21: PAT | C21: ='Monthly Actuals'!AF22 -> 351.0432 | D21: =D19-D20 -> 295.05072 | E21: =E19-E20 -> 285.52263 | F21: =F19-F20 -> 303.94344 | G21: =G19-G20 -> 331.57466 | H21: =H19-H20 -> 288.70972 | I21: =I19-I20 -> 307.33615 | J21: =J19-J20 -> 335.2758 | K21: =K19-K20 -> 343.78874 | ... O21: =O19-O20 -> 345.42839
B22: PAT Margin % | C22: =C21/C8 -> 0.15288374 | D22: =D21/D8 -> 0.14359294 | E22: =E21/E8 -> 0.14571485 | F22: =F21/F8 -> 0.14571485 | G22: =G21/G8 -> 0.14571485 | H22: =H21/H8 -> 0.14673219 | I22: =I21/I8 -> 0.14673219 | J22: =J21/J8 -> 0.14673219 | ... O22: =O21/O8 -> 0.14653093
B24: 12-Month Rolling Forecast Total
B25: Revenue (12-mo sum) | C25: =SUM(D8:O8) -> 26852.104
B26: EBITDA (12-mo sum) | C26: =SUM(D13:O13) -> 5907.4629
B27: PAT (12-mo sum) | C27: =SUM(D21:O21) -> 3926.3308

Sheet Budget VS Actuals
B2: ="Budget vs Actual (Apr-26 to Jun-26) -"&'Data Sheet'!B1 -> Budget vs Actual (Apr-26 to Jun-26) -NESTLE INDIA LTD
B4: Month | C4: 46113 | D4: 46143 | E4: 46174
B6: Revenue
B7: Budget | C7: ='Monthly Budget'!C7 -> 2179.5365 | D7: ='Monthly Budget'!D7 -> 1737.7906 | E7: ='Monthly Budget'!E7 -> 1849.9061
B8: Actual (Derived) | C8: ='Monthly Actuals'!AD9 -> 1977.2358 | D8: ='Monthly Actuals'!AE9 -> 2104.7994 | E8: ='Monthly Actuals'!AF9 -> 2296.1448
B9: Variance | C9: =C8-C7 -> -202.30068 | D9: =D8-D7 -> 367.00884 | E9: =E8-E7 -> 446.23872
B10: Variance % | C10: =IFERROR((C8-C7)/ABS(C7),0) -> -0.092818212 | D10: =IFERROR((D8-D7)/ABS(D7),0) -> 0.21119279 | E10: =IFERROR((E8-E7)/ABS(E7),0) -> 0.24122237
B12: COGS
B13: Budget | C13: ='Monthly Budget'!C9 -> 845.66015 | D13: ='Monthly Budget'!D9 -> 674.26274 | E13: ='Monthly Budget'!E9 -> 717.76356
B14: Actual (Derived) | C14: ='Monthly Actuals'!AD11 -> 742.70567 | D14: ='Monthly Actuals'!AE11 -> 790.62217 | E14: ='Monthly Actuals'!AF11 -> 862.49691
B15: Variance | C15: =C14-C13 -> -102.95448 | D15: =D14-D13 -> 116.35943 | E15: =E14-E13 -> 144.73335
B16: Variance % | C16: =IFERROR((C14-C13)/ABS(C13),0) -> -0.12174451 | D16: =IFERROR((D14-D13)/ABS(D13),0) -> 0.17257283 | E16: =IFERROR((E14-E13)/ABS(E13),0) -> 0.20164489
B18: Employee Cost
B19: Budget | C19: ='Monthly Budget'!C10 -> 222.31272 | D19: ='Monthly Budget'!D10 -> 177.25464 | E19: ='Monthly Budget'!E10 -> 188.69042
B20: Actual (Derived) | C20: ='Monthly Actuals'!AD12 -> 198.05485 | D20: ='Monthly Actuals'!AE12 -> 210.83258 | E20: ='Monthly Actuals'!AF12 -> 229.99918
B21: Variance | C21: =C20-C19 -> -24.257875 | D21: =D20-D19 -> 33.577941 | E21: =E20-E19 -> 41.308756
B22: Variance % | C22: =IFERROR((C20-C19)/ABS(C19),0) -> -0.109116 | D22: =IFERROR((D20-D19)/ABS(D19),0) -> 0.18943336 | E22: =IFERROR((E20-E19)/ABS(E19),0) -> 0.21892344
B24: Other Operating Expenses
B25: Budget | C25: ='Monthly Budget'!C11 -> 612.44975 | D25: ='Monthly Budget'!D11 -> 488.31915 | E25: ='Monthly Budget'!E11 -> 519.82361
B26: Actual (Derived) | C26: ='Monthly Actuals'!AD13 -> 559.65498 | D26: ='Monthly Actuals'!AE13 -> 595.76175 | E26: ='Monthly Actuals'!AF13 -> 649.92191
B27: Variance | C27: =C26-C25 -> -52.794769 | D27: =D26-D25 -> 107.44261 | E27: =E26-E25 -> 130.09831
B28: Variance % | C28: =IFERROR((C26-C25)/ABS(C25),0) -> -0.086202614 | D28: =IFERROR((D26-D25)/ABS(D25),0) -> 0.22002538 | E28: =IFERROR((E26-E25)/ABS(E25),0) -> 0.25027395
B30: EBITDA
B31: Budget | C31: ='Monthly Budget'!C12 -> 499.11385 | D31: ='Monthly Budget'!D12 -> 397.95404 | E31: ='Monthly Budget'!E12 -> 423.62849
B32: Actual (Derived) | C32: ='Monthly Actuals'!AD14 -> 476.8203 | D32: ='Monthly Actuals'!AE14 -> 507.5829 | E32: ='Monthly Actuals'!AF14 -> 553.7268
B33: Variance | C33: =C32-C31 -> -22.293554 | D33: =D32-D31 -> 109.62886 | E33: =E32-E31 -> 130.09831
B34: Variance % | C34: =IFERROR((C32-C31)/ABS(C31),0) -> -0.04466627 | D34: =IFERROR((D32-D31)/ABS(D31),0) -> 0.27548121 | E34: =IFERROR((E32-E31)/ABS(E31),0) -> 0.30710472
B36: Depreciation
B37: Budget | C37: ='Monthly Budget'!C15 -> 53.711146 | D37: ='Monthly Budget'!D15 -> 57.176381 | E37: ='Monthly Budget'!E15 -> 62.374234
B38: Actual (Derived) | C38: ='Monthly Actuals'!AD17 -> 58.218 | D38: ='Monthly Actuals'!AE17 -> 61.974 | E38: ='Monthly Actuals'!AF17 -> 67.608
B39: Variance | C39: =C38-C37 -> 4.5068544 | D39: =D38-D37 -> 4.7976192 | E39: =E38-E37 -> 5.2337664
B40: Variance % | C40: =IFERROR((C38-C37)/ABS(C37),0) -> 0.08390911 | D40: =IFERROR((D38-D37)/ABS(D37),0) -> 0.08390911 | E40: =IFERROR((E38-E37)/ABS(E37),0) -> 0.08390911
B42: Interest
B43: Budget | C43: ='Monthly Budget'!C17 -> 15.626092 | D43: ='Monthly Budget'!D17 -> 16.634228 | E43: ='Monthly Budget'!E17 -> 18.14643
B44: Actual (Derived) | C44: ='Monthly Actuals'!AD19 -> 13.0758 | D44: ='Monthly Actuals'!AE19 -> 13.9194 | E44: ='Monthly Actuals'!AF19 -> 15.1848
B45: Variance | C45: =C44-C43 -> -2.5502925 | D45: =D44-D43 -> -2.7148275 | E45: =E44-E43 -> -2.96163
